Workbook

Sheet Dashboard
A1: NYDG LOI Options - Executive Summary
A2: All values reference the Inputs sheet - change inputs to update all calculations
A4: SIDE-BY-SIDE COMPARISON
A5: Metric | B5: Option A (Aggressive) | C5: Option B (Balanced) | D5: Option C (Premium) | E5: Notes
A6: Headline Price | B6: =Inputs!B12 | C6: =Inputs!C12 | D6: =Inputs!D12 | E6: Enterprise Value
A7: Initial Purchase (40%) | B7: =Inputs!B32 | C7: =Inputs!C32 | D7: =Inputs!D32
A8: Down Payment | B8: =Inputs!B33 | C8: =Inputs!C33 | D8: =Inputs!D33 | E8: 10% of initial tranche
A9: Seller Note | B9: =Inputs!B34 | C9: =Inputs!C34 | D9: =Inputs!D34 | E9: Financed amount
A10: Note Term | B10: =Inputs!B15 | C10: =Inputs!C15 | D10: =Inputs!D15 | E10: Years
A11: 0% Interest Period | B11: =Inputs!B16 | C11: =Inputs!C16 | D11: =Inputs!D16 | E11: Years
A12: Total Consulting | B12: =Inputs!B36 | C12: =Inputs!C36 | D12: =Inputs!D36
A13: Grand Total Nominal | B13: =Inputs!B12+Inputs!B36 | C13: =Inputs!C12+Inputs!C36 | D13: =Inputs!D12+Inputs!D36 | E13: Including consulting
A15: PRESENT VALUE ANALYSIS
A16: Component | B16: Option A | C16: Option B | D16: Option C | E16: Formula Logic
A17: Down Payment (PV) | B17: =Inputs!B33 | C17: =Inputs!C33 | D17: =Inputs!D33 | E17: No discount - paid at close
A18: Est. Phase 1 Payments PV | B18: ="~"&TEXT(Inputs!B34*0.6,"$#,##0") | C18: ="~"&TEXT(Inputs!C34*0.65,"$#,##0") | D18: ="~"&TEXT(Inputs!D34*0.55,"$#,##0") | E18: Discounted at PV rate
A19: Est. Future Tranches PV | B19: ="~"&TEXT(Inputs!B35*0.55,"$#,##0") | C19: ="~"&TEXT(Inputs!C35*0.58,"$#,##0") | D19: ="~"&TEXT(Inputs!D35*0.50,"$#,##0") | E19: Heavily discounted
A20: Total Est. PV | B20: =Inputs!B33+Inputs!B34*0.6+Inputs!B35*0.55 | C20: =Inputs!C33+Inputs!C34*0.65+Inputs!C35*0.58 | D20: =Inputs!D33+Inputs!D34*0.55+Inputs!D35*0.50 | E20: Sum of components
A21: PV as % of Headline | B21: =(Inputs!B33+Inputs!B34*0.6+Inputs!B35*0.55)/Inputs!B12 | C21: =(Inputs!C33+Inputs!C34*0.65+Inputs!C35*0.58)/Inputs!C12 | D21: =(Inputs!D33+Inputs!D34*0.55+Inputs!D35*0.50)/Inputs!D12 | E21: True cost %
A24: EXTERNAL BUYER COMPARISON
A25: External Buyer EV (Low) | B25: =Inputs!B5*Inputs!B25 | E25: =Inputs!B25&"x EBITDA"
A26: External Buyer EV (High) | B26: =Inputs!B5*Inputs!B26 | E26: =Inputs!B26&"x EBITDA"
A27: Less: Debt Payoff | B27: =-Inputs!B6
A28: External Equity Value (Low) | B28: =Inputs!B5*Inputs!B25-Inputs!B6 | E28: What external pays
A29: External Equity Value (High) | B29: =Inputs!B5*Inputs!B26-Inputs!B6
A31: Belkin MBO Premium (vs Low) | B31: =Inputs!B12-(Inputs!B5*Inputs!B25-Inputs!B6) | C31: =Inputs!C12-(Inputs!B5*Inputs!B25-Inputs!B6) | D31: =Inputs!D12-(Inputs!B5*Inputs!B25-Inputs!B6) | E31: Premium over external

Sheet Inputs
A1: NYDG LOI Calculator - Input Parameters
A3: PRACTICE FUNDAMENTALS
A4: 2025 Revenue | B4: 13732000
A5: 2025 EBITDA (Est.) | B5: 2932000
A6: BofA Loan Outstanding | B6: 2205200
A7: Belkin 2025 Billings | B7: 5450000
A8: Belkin % of Revenue | B8: =B7/B4
A10: OPTION PARAMETERS
B11: Option A | C11: Option B | D11: Option C
A12: Enterprise Value | B12: 6500000 | C12: 8000000 | D12: 10000000
A13: Initial Purchase % | B13: 0.4 | C13: 0.4 | D13: 0.4
A14: Down Payment % | B14: 0.1 | C14: 0.1 | D14: 0.1
A15: Note Term (Years) | B15: 10 | C15: 7 | D15: 10
A16: 0% Interest Period (Years) | B16: 5 | C16: 3 | D16: 5
A17: Interest Rate (AFR) | B17: 0.045 | C17: 0.045 | D17: 0.045
A18: Amortization (Years) | B18: 20 | C18: 15 | D18: 25
A19: Consulting ($/yr) | B19: 0 | C19: 0 | D19: 150000
A20: Consulting Years | B20: 0 | C20: 0 | D20: 5
A23: VALUATION & DISCOUNT PARAMETERS
A24: PV Discount Rate | B24: 0.08
A25: External Buyer Low Multiple | B25: 4.5
A26: External Buyer High Multiple | B26: 5.5
A27: MBO Low Multiple | B27: 5.75
A28: MBO High Multiple | B28: 6.75
A29: Key Person Risk Discount | B29: 0.15
A31: CALCULATED VALUES (Reference)
A32: Initial Purchase Price | B32: =B12*B13 | C32: =C12*C13 | D32: =D12*D13
A33: Down Payment Amount | B33: =B32*B14 | C33: =C32*C14 | D33: =D32*D14
A34: Seller Note Amount | B34: =B32-B33 | C34: =C32-C33 | D34: =D32-D33
A35: Remaining 60% Value | B35: =B12*(1-B13) | C35: =C12*(1-C13) | D35: =D12*(1-D13)
A36: Total Consulting Value | B36: =B19*B20 | C36: =C19*C20 | D36: =D19*D20

Sheet Schedule_A
A1: Payment Schedule - Option A
A3: Key Inputs (from Inputs sheet)
A4: Enterprise Value | B4: =Inputs!B12
A5: Initial Purchase Amount | B5: =Inputs!B32
A6: Down Payment | B6: =Inputs!B33
A7: Seller Note | B7: =Inputs!B34
A8: Note Term | B8: =Inputs!B15
A9: 0% Period | B9: =Inputs!B16
A10: Interest Rate | B10: =Inputs!B17
A11: Amortization | B11: =Inputs!B18
A13: Phase 1 Payment Schedule (40% Purchase)
A14: Year | B14: Beginning Balance | C14: Payment | D14: Interest | E14: Principal | F14: Ending Balance | G14: Cumulative Paid
A15: 0 | B15: =Inputs!B34 | C15: =Inputs!B33 | D15: 0 | E15: =Inputs!B33 | F15: =Inputs!B34 | G15: =C15
A16: 1 | B16: =F15 | C16: =IF(A16<=B8,B7/B11,0) | D16: =IF(A16<=B9,0,B16*B10) | E16: =C16-D16 | F16: =MAX(0,B16-E16) | G16: =G15+C16
A17: 2 | B17: =F16 | C17: =IF(A17<=B8,B7/B11,0) | D17: =IF(A17<=B9,0,B17*B10) | E17: =C17-D17 | F17: =MAX(0,B17-E17) | G17: =G16+C17
A18: 3 | B18: =F17 | C18: =IF(A18<=B8,B7/B11,0) | D18: =IF(A18<=B9,0,B18*B10) | E18: =C18-D18 | F18: =MAX(0,B18-E18) | G18: =G17+C18
A19: 4 | B19: =F18 | C19: =IF(A19<=B8,B7/B11,0) | D19: =IF(A19<=B9,0,B19*B10) | E19: =C19-D19 | F19: =MAX(0,B19-E19) | G19: =G18+C19
A20: 5 | B20: =F19 | C20: =IF(A20<=B8,B7/B11,0) | D20: =IF(A20<=B9,0,B20*B10) | E20: =C20-D20 | F20: =MAX(0,B20-E20) | G20: =G19+C20
A21: 6 | B21: =F20 | C21: =IF(A21<=B8,B7/B11,0) | D21: =IF(A21<=B9,0,B21*B10) | E21: =C21-D21 | F21: =MAX(0,B21-E21) | G21: =G20+C21
A22: 7 | B22: =F21 | C22: =IF(A22<=B8,B7/B11,0) | D22: =IF(A22<=B9,0,B22*B10) | E22: =C22-D22 | F22: =MAX(0,B22-E22) | G22: =G21+C22
A23: 8 | B23: =F22 | C23: =IF(A23<=B8,B7/B11,0) | D23: =IF(A23<=B9,0,B23*B10) | E23: =C23-D23 | F23: =MAX(0,B23-E23) | G23: =G22+C23
A24: 9 | B24: =F23 | C24: =IF(A24<=B8,B7/B11,0) | D24: =IF(A24<=B9,0,B24*B10) | E24: =C24-D24 | F24: =MAX(0,B24-E24) | G24: =G23+C24
A25: 10 | B25: =F24 | C25: =IF(A25<=B8,B7/B11,0) | D25: =IF(A25<=B9,0,B25*B10) | E25: =C25-D25 | F25: =MAX(0,B25-E25) | G25: =G24+C25
A26: 11 | B26: =F25 | C26: =IF(A26<=B8,B7/B11,0) | D26: =IF(A26<=B9,0,B26*B10) | E26: =C26-D26 | F26: =MAX(0,B26-E26) | G26: =G25+C26
A27: 12 | B27: =F26 | C27: =IF(A27<=B8,B7/B11,0) | D27: =IF(A27<=B9,0,B27*B10) | E27: =C27-D27 | F27: =MAX(0,B27-E27) | G27: =G26+C27
A28: Total | C28: =SUM(C15:C27) | D28: =SUM(D15:D27) | E28: =SUM(E15:E27) | G28: =G27
A31: Present Value Calculation
A32: Discount Rate | B32: =Inputs!B24
A34: Year | B34: Payment | C34: PV Factor | D34: Present Value
A35: 0 | B35: =C15 | C35: =1/(1+$B$32)^A35 | D35: =B35*C35
A36: 1 | B36: =C16 | C36: =1/(1+$B$32)^A36 | D36: =B36*C36
A37: 2 | B37: =C17 | C37: =1/(1+$B$32)^A37 | D37: =B37*C37
A38: 3 | B38: =C18 | C38: =1/(1+$B$32)^A38 | D38: =B38*C38
A39: 4 | B39: =C19 | C39: =1/(1+$B$32)^A39 | D39: =B39*C39
A40: 5 | B40: =C20 | C40: =1/(1+$B$32)^A40 | D40: =B40*C40
A41: 6 | B41: =C21 | C41: =1/(1+$B$32)^A41 | D41: =B41*C41
A42: 7 | B42: =C22 | C42: =1/(1+$B$32)^A42 | D42: =B42*C42
A43: 8 | B43: =C23 | C43: =1/(1+$B$32)^A43 | D43: =B43*C43
A44: 9 | B44: =C24 | C44: =1/(1+$B$32)^A44 | D44: =B44*C44
A45: 10 | B45: =C25 | C45: =1/(1+$B$32)^A45 | D45: =B45*C45
...

Sheet Schedule_B
A1: Payment Schedule - Option B
A3: Key Inputs (from Inputs sheet)
A4: Enterprise Value | B4: =Inputs!C12
A5: Initial Purchase Amount | B5: =Inputs!C32
A6: Down Payment | B6: =Inputs!C33
A7: Seller Note | B7: =Inputs!C34
A8: Note Term | B8: =Inputs!C15
A9: 0% Period | B9: =Inputs!C16
A10: Interest Rate | B10: =Inputs!C17
A11: Amortization | B11: =Inputs!C18
A13: Phase 1 Payment Schedule (40% Purchase)
A14: Year | B14: Beginning Balance | C14: Payment | D14: Interest | E14: Principal | F14: Ending Balance | G14: Cumulative Paid
A15: 0 | B15: =Inputs!C34 | C15: =Inputs!C33 | D15: 0 | E15: =Inputs!C33 | F15: =Inputs!C34 | G15: =C15
A16: 1 | B16: =F15 | C16: =IF(A16<=B8,B7/B11,0) | D16: =IF(A16<=B9,0,B16*B10) | E16: =C16-D16 | F16: =MAX(0,B16-E16) | G16: =G15+C16
A17: 2 | B17: =F16 | C17: =IF(A17<=B8,B7/B11,0) | D17: =IF(A17<=B9,0,B17*B10) | E17: =C17-D17 | F17: =MAX(0,B17-E17) | G17: =G16+C17
A18: 3 | B18: =F17 | C18: =IF(A18<=B8,B7/B11,0) | D18: =IF(A18<=B9,0,B18*B10) | E18: =C18-D18 | F18: =MAX(0,B18-E18) | G18: =G17+C18
A19: 4 | B19: =F18 | C19: =IF(A19<=B8,B7/B11,0) | D19: =IF(A19<=B9,0,B19*B10) | E19: =C19-D19 | F19: =MAX(0,B19-E19) | G19: =G18+C19
A20: 5 | B20: =F19 | C20: =IF(A20<=B8,B7/B11,0) | D20: =IF(A20<=B9,0,B20*B10) | E20: =C20-D20 | F20: =MAX(0,B20-E20) | G20: =G19+C20
A21: 6 | B21: =F20 | C21: =IF(A21<=B8,B7/B11,0) | D21: =IF(A21<=B9,0,B21*B10) | E21: =C21-D21 | F21: =MAX(0,B21-E21) | G21: =G20+C21
A22: 7 | B22: =F21 | C22: =IF(A22<=B8,B7/B11,0) | D22: =IF(A22<=B9,0,B22*B10) | E22: =C22-D22 | F22: =MAX(0,B22-E22) | G22: =G21+C22
A23: 8 | B23: =F22 | C23: =IF(A23<=B8,B7/B11,0) | D23: =IF(A23<=B9,0,B23*B10) | E23: =C23-D23 | F23: =MAX(0,B23-E23) | G23: =G22+C23
A24: 9 | B24: =F23 | C24: =IF(A24<=B8,B7/B11,0) | D24: =IF(A24<=B9,0,B24*B10) | E24: =C24-D24 | F24: =MAX(0,B24-E24) | G24: =G23+C24
A25: 10 | B25: =F24 | C25: =IF(A25<=B8,B7/B11,0) | D25: =IF(A25<=B9,0,B25*B10) | E25: =C25-D25 | F25: =MAX(0,B25-E25) | G25: =G24+C25
A26: 11 | B26: =F25 | C26: =IF(A26<=B8,B7/B11,0) | D26: =IF(A26<=B9,0,B26*B10) | E26: =C26-D26 | F26: =MAX(0,B26-E26) | G26: =G25+C26
A27: 12 | B27: =F26 | C27: =IF(A27<=B8,B7/B11,0) | D27: =IF(A27<=B9,0,B27*B10) | E27: =C27-D27 | F27: =MAX(0,B27-E27) | G27: =G26+C27
A28: Total | C28: =SUM(C15:C27) | D28: =SUM(D15:D27) | E28: =SUM(E15:E27) | G28: =G27
A31: Present Value Calculation
A32: Discount Rate | B32: =Inputs!B24
A34: Year | B34: Payment | C34: PV Factor | D34: Present Value
A35: 0 | B35: =C15 | C35: =1/(1+$B$32)^A35 | D35: =B35*C35
A36: 1 | B36: =C16 | C36: =1/(1+$B$32)^A36 | D36: =B36*C36
A37: 2 | B37: =C17 | C37: =1/(1+$B$32)^A37 | D37: =B37*C37
A38: 3 | B38: =C18 | C38: =1/(1+$B$32)^A38 | D38: =B38*C38
A39: 4 | B39: =C19 | C39: =1/(1+$B$32)^A39 | D39: =B39*C39
A40: 5 | B40: =C20 | C40: =1/(1+$B$32)^A40 | D40: =B40*C40
A41: 6 | B41: =C21 | C41: =1/(1+$B$32)^A41 | D41: =B41*C41
A42: 7 | B42: =C22 | C42: =1/(1+$B$32)^A42 | D42: =B42*C42
A43: 8 | B43: =C23 | C43: =1/(1+$B$32)^A43 | D43: =B43*C43
A44: 9 | B44: =C24 | C44: =1/(1+$B$32)^A44 | D44: =B44*C44
A45: 10 | B45: =C25 | C45: =1/(1+$B$32)^A45 | D45: =B45*C45
...

Sheet Schedule_C
A1: Payment Schedule - Option C
A3: Key Inputs (from Inputs sheet)
A4: Enterprise Value | B4: =Inputs!D12
A5: Initial Purchase Amount | B5: =Inputs!D32
A6: Down Payment | B6: =Inputs!D33
A7: Seller Note | B7: =Inputs!D34
A8: Note Term | B8: =Inputs!D15
A9: 0% Period | B9: =Inputs!D16
A10: Interest Rate | B10: =Inputs!D17
A11: Amortization | B11: =Inputs!D18
A13: Phase 1 Payment Schedule (40% Purchase)
A14: Year | B14: Beginning Balance | C14: Payment | D14: Interest | E14: Principal | F14: Ending Balance | G14: Cumulative Paid
A15: 0 | B15: =Inputs!D34 | C15: =Inputs!D33 | D15: 0 | E15: =Inputs!D33 | F15: =Inputs!D34 | G15: =C15
A16: 1 | B16: =F15 | C16: =IF(A16<=B8,B7/B11,0) | D16: =IF(A16<=B9,0,B16*B10) | E16: =C16-D16 | F16: =MAX(0,B16-E16) | G16: =G15+C16
A17: 2 | B17: =F16 | C17: =IF(A17<=B8,B7/B11,0) | D17: =IF(A17<=B9,0,B17*B10) | E17: =C17-D17 | F17: =MAX(0,B17-E17) | G17: =G16+C17
A18: 3 | B18: =F17 | C18: =IF(A18<=B8,B7/B11,0) | D18: =IF(A18<=B9,0,B18*B10) | E18: =C18-D18 | F18: =MAX(0,B18-E18) | G18: =G17+C18
A19: 4 | B19: =F18 | C19: =IF(A19<=B8,B7/B11,0) | D19: =IF(A19<=B9,0,B19*B10) | E19: =C19-D19 | F19: =MAX(0,B19-E19) | G19: =G18+C19
A20: 5 | B20: =F19 | C20: =IF(A20<=B8,B7/B11,0) | D20: =IF(A20<=B9,0,B20*B10) | E20: =C20-D20 | F20: =MAX(0,B20-E20) | G20: =G19+C20
A21: 6 | B21: =F20 | C21: =IF(A21<=B8,B7/B11,0) | D21: =IF(A21<=B9,0,B21*B10) | E21: =C21-D21 | F21: =MAX(0,B21-E21) | G21: =G20+C21
A22: 7 | B22: =F21 | C22: =IF(A22<=B8,B7/B11,0) | D22: =IF(A22<=B9,0,B22*B10) | E22: =C22-D22 | F22: =MAX(0,B22-E22) | G22: =G21+C22
A23: 8 | B23: =F22 | C23: =IF(A23<=B8,B7/B11,0) | D23: =IF(A23<=B9,0,B23*B10) | E23: =C23-D23 | F23: =MAX(0,B23-E23) | G23: =G22+C23
A24: 9 | B24: =F23 | C24: =IF(A24<=B8,B7/B11,0) | D24: =IF(A24<=B9,0,B24*B10) | E24: =C24-D24 | F24: =MAX(0,B24-E24) | G24: =G23+C24
A25: 10 | B25: =F24 | C25: =IF(A25<=B8,B7/B11,0) | D25: =IF(A25<=B9,0,B25*B10) | E25: =C25-D25 | F25: =MAX(0,B25-E25) | G25: =G24+C25
A26: 11 | B26: =F25 | C26: =IF(A26<=B8,B7/B11,0) | D26: =IF(A26<=B9,0,B26*B10) | E26: =C26-D26 | F26: =MAX(0,B26-E26) | G26: =G25+C26
A27: 12 | B27: =F26 | C27: =IF(A27<=B8,B7/B11,0) | D27: =IF(A27<=B9,0,B27*B10) | E27: =C27-D27 | F27: =MAX(0,B27-E27) | G27: =G26+C27
A28: Total | C28: =SUM(C15:C27) | D28: =SUM(D15:D27) | E28: =SUM(E15:E27) | G28: =G27
A31: Present Value Calculation
A32: Discount Rate | B32: =Inputs!B24
A34: Year | B34: Payment | C34: PV Factor | D34: Present Value
A35: 0 | B35: =C15 | C35: =1/(1+$B$32)^A35 | D35: =B35*C35
A36: 1 | B36: =C16 | C36: =1/(1+$B$32)^A36 | D36: =B36*C36
A37: 2 | B37: =C17 | C37: =1/(1+$B$32)^A37 | D37: =B37*C37
A38: 3 | B38: =C18 | C38: =1/(1+$B$32)^A38 | D38: =B38*C38
A39: 4 | B39: =C19 | C39: =1/(1+$B$32)^A39 | D39: =B39*C39
A40: 5 | B40: =C20 | C40: =1/(1+$B$32)^A40 | D40: =B40*C40
A41: 6 | B41: =C21 | C41: =1/(1+$B$32)^A41 | D41: =B41*C41
A42: 7 | B42: =C22 | C42: =1/(1+$B$32)^A42 | D42: =B42*C42
A43: 8 | B43: =C23 | C43: =1/(1+$B$32)^A43 | D43: =B43*C43
A44: 9 | B44: =C24 | C44: =1/(1+$B$32)^A44 | D44: =B44*C44
A45: 10 | B45: =C25 | C45: =1/(1+$B$32)^A45 | D45: =B45*C45
...

Sheet Perspectives
A1: Seller vs Buyer Perspectives
A3: COLBERT'S PERSPECTIVE (What Seller Sees)
A4: What Matters to Colbert | B4: Option A | C4: Option B | D4: Option C | E4: Winner
A5: Headline Number | B5: =Inputs!B12 | C5: =Inputs!C12 | D5: =Inputs!D12 | E5: Option C
A6: Cash at Close | B6: =Inputs!B33 | C6: =Inputs!C33 | D6: =Inputs!D33 | E6: Option C
A7: Annual Income Y1-5 (note only) | B7: =Inputs!B34/Inputs!B18 | C7: =Inputs!C34/Inputs!C18 | D7: =Inputs!D34/Inputs!D18 | E7: Option B
A8: + Consulting | B8: =Inputs!B19 | C8: =Inputs!C19 | D8: =Inputs!D19 | E8: Option C
A9: Total Annual Y1-5 | B9: =Inputs!B34/Inputs!B18+Inputs!B19 | C9: =Inputs!C34/Inputs!C18+Inputs!C19 | D9: =Inputs!D34/Inputs!D18+Inputs!D19 | E9: Option C
A10: Legacy/Pride Factor | B10: "Modest" | C10: "Fair" | D10: "Premium" | E10: Option C
A11: Total Nominal Received | B11: =Inputs!B12+Inputs!B36 | C11: =Inputs!C12+Inputs!C36 | D11: =Inputs!D12+Inputs!D36 | E11: Option C
A14: BELKIN'S PERSPECTIVE (True Economics)
A15: What Matters to Belkin | B15: Option A | C15: Option B | D15: Option C | E15: Best Value
A16: Headline (Face Value) | B16: =Inputs!B12 | C16: =Inputs!C12 | D16: =Inputs!D12
A17: Est. Present Value | B17: =Inputs!B33+Inputs!B34*0.6+Inputs!B35*0.55 | C17: =Inputs!C33+Inputs!C34*0.65+Inputs!C35*0.58 | D17: =Inputs!D33+Inputs!D34*0.55+Inputs!D35*0.50 | E17: Option A
A18: PV per $1 Headline | B18: =(Inputs!B33+Inputs!B34*0.6+Inputs!B35*0.55)/Inputs!B12 | C18: =(Inputs!C33+Inputs!C34*0.65+Inputs!C35*0.58)/Inputs!C12 | D18: =(Inputs!D33+Inputs!D34*0.55+Inputs!D35*0.50)/Inputs!D12 | E18: Option C
A19: Out-of-Pocket Year 1 | B19: =Inputs!B33+Inputs!B34/Inputs!B18+Inputs!B19 | C19: =Inputs!C33+Inputs!C34/Inputs!C18+Inputs!C19 | D19: =Inputs!D33+Inputs!D34/Inputs!D18+Inputs!D19 | E19: Option A
A20: Years Interest-Free | B20: =Inputs!B16 | C20: =Inputs!C16 | D20: =Inputs!D16 | E20: A or C
A21: Negotiation Flexibility | B21: "High" | C21: "Medium" | D21: "Low" | E21: Option A
A22: Relationship Preservation | B22: "Risky" | C22: "Good" | D22: "Excellent" | E22: Option C
A25: KEY INSIGHT
A26: Option C costs ~14% more in PV than Option B, but gives 25% higher headline. "PV per $1 Headline" is lowest for Option C = best value per dollar of perceived price. Lead with Option C - it optimizes for psychology while minimizing true cost.

Sheet Scenarios
A1: What-If Scenario Analysis
A3: Adjust the yellow cells to see how different scenarios affect the deal
A5: SCENARIO INPUTS
A6: Custom Enterprise Value | B6: 8500000
A7: Custom Down Payment % | B7: 0.15
A8: Custom 0% Interest Period | B8: 4
A9: Custom Note Term | B9: 8
A10: Custom Interest Rate (AFR) | B10: 0.045
A11: Custom Amortization Years | B11: 20
A12: Custom Consulting $/Year | B12: 100000
A13: Custom Consulting Years | B13: 3
A15: SCENARIO RESULTS
A16: Initial Purchase (40%) | B16: =B6*0.4
A17: Down Payment | B17: =B16*B7
A18: Seller Note | B18: =B16-B17
A19: Est. Annual Payment (0% period) | B19: =B18/B11
A20: Remaining 60% | B20: =B6*0.6
A21: Total Consulting | B21: =B12*B13
A22: Grand Total Nominal | B22: =B6+B21
A24: Est. PV (rough) | B24: =B17+B18*0.6+B20*0.55+B21*0.7
A25: PV as % of Headline | B25: =B24/B6
A27: COMPARISON TO BASE OPTIONS
A28: Metric | B28: Your Scenario | C28: Option B | D28: Option C
A29: Headline | B29: =B6 | C29: =Inputs!C12 | D29: =Inputs!D12
A30: Down Payment | B30: =B17 | C30: =Inputs!C33 | D30: =Inputs!D33
A31: Est. PV | B31: =B24 | C31: =Inputs!C33+Inputs!C34*0.65+Inputs!C35*0.58 | D31: =Inputs!D33+Inputs!D34*0.55+Inputs!D35*0.50
A32: PV/Headline | B32: =B25 | C32: =(Inputs!C33+Inputs!C34*0.65+Inputs!C35*0.58)/Inputs!C12 | D32: =(Inputs!D33+Inputs!D34*0.55+Inputs!D35*0.50)/Inputs!D12
